<?xml version="1.0"?>
<!-- This is a file generated by Grok from the go2.xml file -->
<robot name="go2">
  <!-- Materials -->
  <material name="metal">
    <color rgba="0.9 0.95 0.95 1"/>
  </material>
  <material name="black">
    <color rgba="0 0 0 1"/>
  </material>
  <material name="white">
    <color rgba="1 1 1 1"/>
  </material>
  <material name="gray">
    <color rgba="0.671705 0.692426 0.774270 1"/>
  </material>

  <!-- Base Link -->
  <link name="base_link">
    <inertial>
      <origin xyz="0.021112 0 -0.005366" rpy="0 0 0"/>
      <mass value="6.921"/>
      <inertia ixx="0.107027" ixy="0" ixz="0" iyy="0.0980771" iyz="0" izz="0.0244531"/>
    </inertial>
    <visual>
      <origin xyz="0 0 0" rpy="0 0 0"/>
      <geometry>
        <mesh filename="./assets/base_0.obj" scale="1 1 1"/>
      </geometry>
      <material name="black"/>
    </visual>
    <visual>
      <origin xyz="0 0 0" rpy="0 0 0"/>
      <geometry>
        <mesh filename="./assets/base_1.obj" scale="1 1 1"/>
      </geometry>
      <material name="black"/>
    </visual>
    <visual>
      <origin xyz="0 0 0" rpy="0 0 0"/>
      <geometry>
        <mesh filename="./assets/base_2.obj" scale="1 1 1"/>
      </geometry>
      <material name="black"/>
    </visual>
    <visual>
      <origin xyz="0 0 0" rpy="0 0 0"/>
      <geometry>
        <mesh filename="./assets/base_3.obj" scale="1 1 1"/>
      </geometry>
      <material name="white"/>
    </visual>
    <visual>
      <origin xyz="0 0 0" rpy="0 0 0"/>
      <geometry>
        <mesh filename="./assets/base_4.obj" scale="1 1 1"/>
      </geometry>
      <material name="gray"/>
    </visual>
    <collision>
      <origin xyz="0 0 0" rpy="0 0 0"/>
      <geometry>
        <box size="0.3762 0.0935 0.114"/>
      </geometry>
    </collision>
    <collision>
      <origin xyz="0.285 0 0.01" rpy="0 0 0"/>
      <geometry>
        <cylinder radius="0.05" length="0.09"/>
      </geometry>
    </collision>
    <collision>
      <origin xyz="0.293 0 -0.06" rpy="0 0 0"/>
      <geometry>
        <sphere radius="0.047"/>
      </geometry>
    </collision>
  </link>

  <!-- Front Left (FL) Leg -->
  <link name="FL_hip">
    <inertial>
      <origin xyz="-0.0054 0.00194 -0.000105" rpy="0 0 0"/>
      <mass value="0.678"/>
      <inertia ixx="0.00088403" ixy="0" ixz="0" iyy="0.000596003" iyz="0" izz="0.000479967"/>
    </inertial>
    <visual>
      <origin xyz="0 0 0" rpy="0 0 0"/>
      <geometry>
        <mesh filename="./assets/hip_0.obj" scale="1 1 1"/>
      </geometry>
      <material name="metal"/>
    </visual>
    <visual>
      <origin xyz="0 0 0" rpy="0 0 0"/>
      <geometry>
        <mesh filename="./assets/hip_1.obj" scale="1 1 1"/>
      </geometry>
      <material name="gray"/>
    </visual>
    <collision>
      <origin xyz="0 0.08 0" rpy="0.785398 0 0"/>
      <geometry>
        <cylinder radius="0.02" length="0.092"/>
      </geometry>
    </collision>
  </link>
  <joint name="FL_hip_joint" type="revolute">
    <parent link="base_link"/>
    <child link="FL_hip"/>
    <origin xyz="0.1934 0.0465 0" rpy="0 0 0"/>
    <axis xyz="1 0 0"/>
    <limit lower="-1.0472" upper="1.0472" effort="23.7" velocity="10"/>
    <dynamics damping="0.1" friction="0.2"/>
  </joint>

  <link name="FL_thigh">
    <inertial>
      <origin xyz="-0.00374 -0.0223 -0.0327" rpy="0 0 0"/>
      <mass value="1.152"/>
      <inertia ixx="0.00594973" ixy="0" ixz="0" iyy="0.00584149" iyz="0" izz="0.000878787"/>
    </inertial>
    <visual>
      <origin xyz="0 0 0" rpy="0 0 0"/>
      <geometry>
        <mesh filename="./assets/thigh_0.obj" scale="1 1 1"/>
      </geometry>
      <material name="metal"/>
    </visual>
    <visual>
      <origin xyz="0 0 0" rpy="0 0 0"/>
      <geometry>
        <mesh filename="./assets/thigh_1.obj" scale="1 1 1"/>
      </geometry>
      <material name="gray"/>
    </visual>
    <collision>
      <origin xyz="0 0 -0.1065" rpy="0.785398 0 0"/>
      <geometry>
        <box size="0.034 0.0245 0.213"/>
      </geometry>
    </collision>
  </link>
  <joint name="FL_thigh_joint" type="revolute">
    <parent link="FL_hip"/>
    <child link="FL_thigh"/>
    <origin xyz="0 0.0955 0" rpy="0 0 0"/>
    <axis xyz="0 1 0"/>
    <limit lower="-1.5708" upper="3.4907" effort="23.7" velocity="10"/>
    <dynamics damping="0.1" friction="0.2"/>
  </joint>

  <link name="FL_calf">
    <inertial>
      <origin xyz="0.00629595 -0.000622121 -0.141417" rpy="0 0 0"/>
      <mass value="0.241352"/>
      <inertia ixx="0.0014901" ixy="0" ixz="0" iyy="0.00146356" iyz="0" izz="5.31397e-05"/>
    </inertial>
    <visual>
      <origin xyz="0 0 0" rpy="0 0 0"/>
      <geometry>
        <mesh filename="./assets/calf_0.obj" scale="1 1 1"/>
      </geometry>
      <material name="gray"/>
    </visual>
    <visual>
      <origin xyz="0 0 0" rpy="0 0 0"/>
      <geometry>
        <mesh filename="./assets/calf_1.obj" scale="1 1 1"/>
      </geometry>
      <material name="black"/>
    </visual>
    <visual>
      <origin xyz="0 0 -0.213" rpy="0 0 0"/>
      <geometry>
        <mesh filename="./assets/foot.obj" scale="1 1 1"/>
      </geometry>
      <material name="black"/>
    </visual>
    <collision>
      <origin xyz="0.008 0 -0.06" rpy="0 -0.105 0"/>
      <geometry>
        <cylinder radius="0.012" length="0.12"/>
      </geometry>
    </collision>
    <collision>
      <origin xyz="0.02 0 -0.148" rpy="0 0.025 0"/>
      <geometry>
        <cylinder radius="0.011" length="0.065"/>
      </geometry>
    </collision>
    <collision>
      <origin xyz="-0.002 0 -0.426" rpy="0 0 0"/>
      <geometry>
        <sphere radius="0.022"/>
      </geometry>
    </collision>
  </link>
  <joint name="FL_calf_joint" type="revolute">
    <parent link="FL_thigh"/>
    <child link="FL_calf"/>
    <origin xyz="0 0 -0.213" rpy="0 0 0"/>
    <axis xyz="0 1 0"/>
    <limit lower="-2.7227" upper="-0.83776" effort="45.43" velocity="10"/>
    <dynamics damping="0.1" friction="0.2"/>
  </joint>

  <!-- Front Right (FR) Leg -->
  <link name="FR_hip">
    <inertial>
      <origin xyz="-0.0054 -0.00194 -0.000105" rpy="0 0 0"/>
      <mass value="0.678"/>
      <inertia ixx="0.00088403" ixy="0" ixz="0" iyy="0.000596003" iyz="0" izz="0.000479967"/>
    </inertial>
    <visual>
      <origin xyz="0 0 0" rpy="0 1.570796 0"/>
      <geometry>
        <mesh filename="./assets/hip_0.obj" scale="1 1 1"/>
      </geometry>
      <material name="metal"/>
    </visual>
    <visual>
      <origin xyz="0 0 0" rpy="0 1.570796 0"/>
      <geometry>
        <mesh filename="./assets/hip_1.obj" scale="1 1 1"/>
      </geometry>
      <material name="gray"/>
    </visual>
    <collision>
      <origin xyz="0 -0.08 0" rpy="0.785398 0 0"/>
      <geometry>
        <cylinder radius="0.02" length="0.092"/>
      </geometry>
    </collision>
  </link>
  <joint name="FR_hip_joint" type="revolute">
    <parent link="base_link"/>
    <child link="FR_hip"/>
    <origin xyz="0.1934 -0.0465 0" rpy="0 0 0"/>
    <axis xyz="1 0 0"/>
    <limit lower="-1.0472" upper="1.0472" effort="23.7" velocity="10"/>
    <dynamics damping="0.1" friction="0.2"/>
  </joint>

  <link name="FR_thigh">
    <inertial>
      <origin xyz="-0.00374 0.0223 -0.0327" rpy="0 0 0"/>
      <mass value="1.152"/>
      <inertia ixx="0.00594973" ixy="0" ixz="0" iyy="0.00584149" iyz="0" izz="0.000878787"/>
    </inertial>
    <visual>
      <origin xyz="0 0 0" rpy="0 0 0"/>
      <geometry>
        <mesh filename="./assets/thigh_mirror_0.obj" scale="1 1 1"/>
      </geometry>
      <material name="metal"/>
    </visual>
    <visual>
      <origin xyz="0 0 0" rpy="0 0 0"/>
      <geometry>
        <mesh filename="./assets/thigh_mirror_1.obj" scale="1 1 1"/>
      </geometry>
      <material name="gray"/>
    </visual>
    <collision>
      <origin xyz="0 0 -0.1065" rpy="0.785398 0 0"/>
      <geometry>
        <box size="0.034 0.0245 0.213"/>
      </geometry>
    </collision>
  </link>
  <joint name="FR_thigh_joint" type="revolute">
    <parent link="FR_hip"/>
    <child link="FR_thigh"/>
    <origin xyz="0 -0.0955 0" rpy="0 0 0"/>
    <axis xyz="0 1 0"/>
    <limit lower="-1.5708" upper="3.4907" effort="23.7" velocity="10"/>
    <dynamics damping="0.1" friction="0.2"/>
  </joint>

  <link name="FR_calf">
    <inertial>
      <origin xyz="0.00629595 0.000622121 -0.141417" rpy="0 0 0"/>
      <mass value="0.241352"/>
      <inertia ixx="0.0014901" ixy="0" ixz="0" iyy="0.00146356" iyz="0" izz="5.31397e-05"/>
    </inertial>
    <visual>
      <origin xyz="0 0 0" rpy="0 0 0"/>
      <geometry>
        <mesh filename="./assets/calf_mirror_0.obj" scale="1 1 1"/>
      </geometry>
      <material name="gray"/>
    </visual>
    <visual>
      <origin xyz="0 0 0" rpy="0 0 0"/>
      <geometry>
        <mesh filename="./assets/calf_mirror_1.obj" scale="1 1 1"/>
      </geometry>
      <material name="black"/>
    </visual>
    <visual>
      <origin xyz="0 0 -0.213" rpy="0 0 0"/>
      <geometry>
        <mesh filename="./assets/foot.obj" scale="1 1 1"/>
      </geometry>
      <material name="black"/>
    </visual>
    <collision>
      <origin xyz="0.01 0 -0.06" rpy="0 -0.1 0"/>
      <geometry>
        <cylinder radius="0.013" length="0.12"/>
      </geometry>
    </collision>
    <collision>
      <origin xyz="0.02 0 -0.148" rpy="0 0.025 0"/>
      <geometry>
        <cylinder radius="0.011" length="0.065"/>
      </geometry>
    </collision>
    <collision>
      <origin xyz="-0.002 0 -0.426" rpy="0 0 0"/>
      <geometry>
        <sphere radius="0.022"/>
      </geometry>
    </collision>
  </link>
  <joint name="FR_calf_joint" type="revolute">
    <parent link="FR_thigh"/>
    <child link="FR_calf"/>
    <origin xyz="0 0 -0.213" rpy="0 0 0"/>
    <axis xyz="0 1 0"/>
    <limit lower="-2.7227" upper="-0.83776" effort="45.43" velocity="10"/>
    <dynamics damping="0.1" friction="0.2"/>
  </joint>

  <!-- Rear Left (RL) Leg -->
  <link name="RL_hip">
    <inertial>
      <origin xyz="0.0054 0.00194 -0.000105" rpy="0 0 0"/>
      <mass value="0.678"/>
      <inertia ixx="0.00088403" ixy="0" ixz="0" iyy="0.000596003" iyz="0" izz="0.000479967"/>
    </inertial>
    <visual>
      <origin xyz="0 0 0" rpy="0 0 1.570796"/>
      <geometry>
        <mesh filename="./assets/hip_0.obj" scale="1 1 1"/>
      </geometry>
      <material name="metal"/>
    </visual>
    <visual>
      <origin xyz="0 0 0" rpy="0 0 1.570796"/>
      <geometry>
        <mesh filename="./assets/hip_1.obj" scale="1 1 1"/>
      </geometry>
      <material name="gray"/>
    </visual>
    <collision>
      <origin xyz="0 0.08 0" rpy="0.785398 0 0"/>
      <geometry>
        <cylinder radius="0.02" length="0.092"/>
      </geometry>
    </collision>
  </link>
  <joint name="RL_hip_joint" type="revolute">
    <parent link="base_link"/>
    <child link="RL_hip"/>
    <origin xyz="-0.1934 0.0465 0" rpy="0 0 0"/>
    <axis xyz="1 0 0"/>
    <limit lower="-1.0472" upper="1.0472" effort="23.7" velocity="10"/>
    <dynamics damping="0.1" friction="0.2"/>
  </joint>

  <link name="RL_thigh">
    <inertial>
      <origin xyz="-0.00374 -0.0223 -0.0327" rpy="0 0 0"/>
      <mass value="1.152"/>
      <inertia ixx="0.00594973" ixy="0" ixz="0" iyy="0.00584149" iyz="0" izz="0.000878787"/>
    </inertial>
    <visual>
      <origin xyz="0 0 0" rpy="0 0 0"/>
      <geometry>
        <mesh filename="./assets/thigh_0.obj" scale="1 1 1"/>
      </geometry>
      <material name="metal"/>
    </visual>
    <visual>
      <origin xyz="0 0 0" rpy="0 0 0"/>
      <geometry>
        <mesh filename="./assets/thigh_1.obj" scale="1 1 1"/>
      </geometry>
      <material name="gray"/>
    </visual>
    <collision>
      <origin xyz="0 0 -0.1065" rpy="0.785398 0 0"/>
      <geometry>
        <box size="0.034 0.0245 0.213"/>
      </geometry>
    </collision>
  </link>
  <joint name="RL_thigh_joint" type="revolute">
    <parent link="RL_hip"/>
    <child link="RL_thigh"/>
    <origin xyz="0 0.0955 0" rpy="0 0 0"/>
    <axis xyz="0 1 0"/>
    <limit lower="-0.5236" upper="4.5379" effort="23.7" velocity="10"/>
    <dynamics damping="0.1" friction="0.2"/>
  </joint>

  <link name="RL_calf">
    <inertial>
      <origin xyz="0.00629595 -0.000622121 -0.141417" rpy="0 0 0"/>
      <mass value="0.241352"/>
      <inertia ixx="0.0014901" ixy="0" ixz="0" iyy="0.00146356" iyz="0" izz="5.31397e-05"/>
    </inertial>
    <visual>
      <origin xyz="0 0 0" rpy="0 0 0"/>
      <geometry>
        <mesh filename="./assets/calf_0.obj" scale="1 1 1"/>
      </geometry>
      <material name="gray"/>
    </visual>
    <visual>
      <origin xyz="0 0 0" rpy="0 0 0"/>
      <geometry>
        <mesh filename="./assets/calf_1.obj" scale="1 1 1"/>
      </geometry>
      <material name="black"/>
    </visual>
    <visual>
      <origin xyz="0 0 -0.213" rpy="0 0 0"/>
      <geometry>
        <mesh filename="./assets/foot.obj" scale="1 1 1"/>
      </geometry>
      <material name="black"/>
    </visual>
    <collision>
      <origin xyz="0.01 0 -0.06" rpy="0 -0.1 0"/>
      <geometry>
        <cylinder radius="0.013" length="0.12"/>
      </geometry>
    </collision>
    <collision>
      <origin xyz="0.02 0 -0.148" rpy="0 0.025 0"/>
      <geometry>
        <cylinder radius="0.011" length="0.065"/>
      </geometry>
    </collision>
    <collision>
      <origin xyz="-0.002 0 -0.426" rpy="0 0 0"/>
      <geometry>
        <sphere radius="0.022"/>
      </geometry>
    </collision>
  </link>
  <joint name="RL_calf_joint" type="revolute">
    <parent link="RL_thigh"/>
    <child link="RL_calf"/>
    <origin xyz="0 0 -0.213" rpy="0 0 0"/>
    <axis xyz="0 1 0"/>
    <limit lower="-2.7227" upper="-0.83776" effort="45.43" velocity="10"/>
    <dynamics damping="0.1" friction="0.2"/>
  </joint>

  <!-- Rear Right (RR) Leg -->
  <link name="RR_hip">
    <inertial>
      <origin xyz="0.0054 -0.00194 -0.000105" rpy="0 0 0"/>
      <mass value="0.678"/>
      <inertia ixx="0.00088403" ixy="0" ixz="0" iyy="0.000596003" iyz="0" izz="0.000479967"/>
    </inertial>
    <visual>
      <origin xyz="0 0 0" rpy="0 0 3.141592"/>
      <geometry>
        <mesh filename="./assets/hip_0.obj" scale="1 1 1"/>
      </geometry>
      <material name="metal"/>
    </visual>
    <visual>
      <origin xyz="0 0 0" rpy="0 0 3.141592"/>
      <geometry>
        <mesh filename="./assets/hip_1.obj" scale="1 1 1"/>
      </geometry>
      <material name="gray"/>
    </visual>
    <collision>
      <origin xyz="0 -0.08 0" rpy="0.785398 0 0"/>
      <geometry>
        <cylinder radius="0.02" length="0.092"/>
      </geometry>
    </collision>
  </link>
  <joint name="RR_hip_joint" type="revolute">
    <parent link="base_link"/>
    <child link="RR_hip"/>
    <origin xyz="-0.1934 -0.0465 0" rpy="0 0 0"/>
    <axis xyz="1 0 0"/>
    <limit lower="-1.0472" upper="1.0472" effort="23.7" velocity="10"/>
    <dynamics damping="0.1" friction="0.2"/>
  </joint>

  <link name="RR_thigh">
    <inertial>
      <origin xyz="-0.00374 0.0223 -0.0327" rpy="0 0 0"/>
      <mass value="1.152"/>
      <inertia ixx="0.00594973" ixy="0" ixz="0" iyy="0.00584149" iyz="0" izz="0.000878787"/>
    </inertial>
    <visual>
      <origin xyz="0 0 0" rpy="0 0 0"/>
      <geometry>
        <mesh filename="./assets/thigh_mirror_0.obj" scale="1 1 1"/>
      </geometry>
      <material name="metal"/>
    </visual>
    <visual>
      <origin xyz="0 0 0" rpy="0 0 0"/>
      <geometry>
        <mesh filename="./assets/thigh_mirror_1.obj" scale="1 1 1"/>
      </geometry>
      <material name="gray"/>
    </visual>
    <collision>
      <origin xyz="0 0 -0.1065" rpy="0.785398 0 0"/>
      <geometry>
        <box size="0.034 0.0245 0.213"/>
      </geometry>
    </collision>
  </link>
  <joint name="RR_thigh_joint" type="revolute">
    <parent link="RR_hip"/>
    <child link="RR_thigh"/>
    <origin xyz="0 -0.0955 0" rpy="0 0 0"/>
    <axis xyz="0 1 0"/>
    <limit lower="-0.5236" upper="4.5379" effort="23.7" velocity="10"/>
    <dynamics damping="0.1" friction="0.2"/>
  </joint>

  <link name="RR_calf">
    <inertial>
      <origin xyz="0.00629595 0.000622121 -0.141417" rpy="0 0 0"/>
      <mass value="0.241352"/>
      <inertia ixx="0.0014901" ixy="0" ixz="0" iyy="0.00146356" iyz="0" izz="5.31397e-05"/>
    </inertial>
    <visual>
      <origin xyz="0 0 0" rpy="0 0 0"/>
      <geometry>
        <mesh filename="./assets/calf_mirror_0.obj" scale="1 1 1"/>
      </geometry>
      <material name="gray"/>
    </visual>
    <visual>
      <origin xyz="0 0 0" rpy="0 0 0"/>
      <geometry>
        <mesh filename="./assets/calf_mirror_1.obj" scale="1 1 1"/>
      </geometry>
      <material name="black"/>
    </visual>
    <visual>
      <origin xyz="0 0 -0.213" rpy="0 0 0"/>
      <geometry>
        <mesh filename="./assets/foot.obj" scale="1 1 1"/>
      </geometry>
      <material name="black"/>
    </visual>
    <collision>
      <origin xyz="0.01 0 -0.06" rpy="0 -0.1 0"/>
      <geometry>
        <cylinder radius="0.013" length="0.12"/>
      </geometry>
    </collision>
    <collision>
      <origin xyz="0.02 0 -0.148" rpy="0 0.025 0"/>
      <geometry>
        <cylinder radius="0.011" length="0.065"/>
      </geometry>
    </collision>
    <collision>
      <origin xyz="-0.002 0 -0.426" rpy="0 0 0"/>
      <geometry>
        <sphere radius="0.022"/>
      </geometry>
    </collision>
  </link>
  <joint name="RR_calf_joint" type="revolute">
    <parent link="RR_thigh"/>
    <child link="RR_calf"/>
    <origin xyz="0 0 -0.213" rpy="0 0 0"/>
    <axis xyz="0 1 0"/>
    <limit lower="-2.7227" upper="-0.83776" effort="45.43" velocity="10"/>
    <dynamics damping="0.1" friction="0.2"/>
  </joint>
</robot>
